<?xml version="1.0"?>
<robot name="MobileManipulator" xmlns:xacro="http://ros.org/wiki/xacro">

  <!-- Webots plugins -->
  <webots>
    <!-- Main mobile base driver -->
    <plugin type="webots_spot.mobile_driver.MobileDriver">
      <differential_drive>true</differential_drive>
      <wheel_separation>0.6</wheel_separation>
      <wheel_radius>0.1</wheel_radius>
    </plugin>

    <!-- IMU sensor -->
    <plugin type="webots_ros2_driver::Ros2IMU">
      <enabled>true</enabled>
      <topicName>/mobile_manipulator/imu</topicName>
      <alwaysOn>true</alwaysOn>
      <frameName>base_link</frameName>
      <inertialUnitName>inertial unit</inertialUnitName>
      <gyroName>gyro</gyroName>
      <accelerometerName>accelerometer</accelerometerName>
    </plugin>

    <!-- Lidar sensor -->
    <plugin type="webots_ros2_driver::Ros2Lidar">
      <enabled>true</enabled>
      <topicName>/scan</topicName>
      <alwaysOn>true</alwaysOn>
      <frameName>lidar_link</frameName>
      <lidarName>lidar</lidarName>
    </plugin>

    <!-- Camera sensor -->
    <plugin type="webots_ros2_driver::Ros2Camera">
      <enabled>true</enabled>
      <topicName>/camera/image_raw</topicName>
      <alwaysOn>true</alwaysOn>
      <frameName>camera_link</frameName>
      <cameraName>camera</cameraName>
    </plugin>

    <!-- ROS2 Control for manipulator -->
    <plugin type="webots_ros2_control::Ros2Control"/>
  </webots>

  <!-- ROS2 Control configuration for manipulator -->
  <ros2_control name="WebotsControl" type="system">
    <hardware>
      <plugin>webots_ros2_control::Ros2ControlSystem</plugin>
    </hardware>

    <!-- Manipulator joints -->
    <joint name="arm_joint_1">
      <command_interface name="position"/>
      <state_interface name="position"/>
      <state_interface name="velocity"/>
    </joint>
    <joint name="arm_joint_2">
      <command_interface name="position"/>
      <state_interface name="position"/>
      <state_interface name="velocity"/>
    </joint>
    <joint name="arm_joint_3">
      <command_interface name="position"/>
      <state_interface name="position"/>
      <state_interface name="velocity"/>
    </joint>
    <joint name="arm_joint_4">
      <command_interface name="position"/>
      <state_interface name="position"/>
      <state_interface name="velocity"/>
    </joint>
    <joint name="arm_joint_5">
      <command_interface name="position"/>
      <state_interface name="position"/>
      <state_interface name="velocity"/>
    </joint>
    <joint name="arm_joint_6">
      <command_interface name="position"/>
      <state_interface name="position"/>
      <state_interface name="velocity"/>
    </joint>

    <!-- Gripper joints -->
    <joint name="gripper_left_joint">
      <command_interface name="position"/>
      <state_interface name="position"/>
      <state_interface name="velocity"/>
    </joint>
    <joint name="gripper_right_joint">
      <command_interface name="position"/>
      <state_interface name="position"/>
      <state_interface name="velocity"/>
    </joint>
  </ros2_control>

  <!-- Materials -->
  <material name="black">
    <color rgba="0.0 0.0 0.0 1.0"/>
  </material>
  <material name="dark_grey">
    <color rgba="0.2 0.2 0.2 1.0"/>
  </material>
  <material name="light_grey">
    <color rgba="0.4 0.4 0.4 1.0"/>
  </material>
  <material name="white">
    <color rgba="1.0 1.0 1.0 1.0"/>
  </material>

  <!-- Base link -->
  <link name="base_link">
    <inertial>
      <origin xyz="0 0 0" rpy="0 0 0"/>
      <mass value="50.0"/>
      <inertia ixx="2.0" ixy="0.0" ixz="0.0" iyy="2.0" iyz="0.0" izz="2.0"/>
    </inertial>
    <visual>
      <origin xyz="0 0 0.05" rpy="0 0 0"/>
      <geometry>
        <box size="0.8 0.6 0.1"/>
      </geometry>
      <material name="dark_grey"/>
    </visual>
    <collision>
      <origin xyz="0 0 0.05" rpy="0 0 0"/>
      <geometry>
        <box size="0.8 0.6 0.1"/>
      </geometry>
    </collision>
  </link>

  <!-- Left wheel -->
  <link name="left_wheel">
    <inertial>
      <origin xyz="0 0 0" rpy="0 0 0"/>
      <mass value="2.0"/>
      <inertia ixx="0.02" ixy="0.0" ixz="0.0" iyy="0.02" iyz="0.0" izz="0.02"/>
    </inertial>
    <visual>
      <origin xyz="0 0 0" rpy="1.5707 0 0"/>
      <geometry>
        <cylinder radius="0.1" length="0.05"/>
      </geometry>
      <material name="black"/>
    </visual>
    <collision>
      <origin xyz="0 0 0" rpy="1.5707 0 0"/>
      <geometry>
        <cylinder radius="0.1" length="0.05"/>
      </geometry>
    </collision>
  </link>

  <!-- Right wheel -->
  <link name="right_wheel">
    <inertial>
      <origin xyz="0 0 0" rpy="0 0 0"/>
      <mass value="2.0"/>
      <inertia ixx="0.02" ixy="0.0" ixz="0.0" iyy="0.02" iyz="0.0" izz="0.02"/>
    </inertial>
    <visual>
      <origin xyz="0 0 0" rpy="1.5707 0 0"/>
      <geometry>
        <cylinder radius="0.1" length="0.05"/>
      </geometry>
      <material name="black"/>
    </visual>
    <collision>
      <origin xyz="0 0 0" rpy="1.5707 0 0"/>
      <geometry>
        <cylinder radius="0.1" length="0.05"/>
      </geometry>
    </collision>
  </link>

  <!-- Wheel joints -->
  <joint name="left_wheel_joint" type="continuous">
    <parent link="base_link"/>
    <child link="left_wheel"/>
    <origin xyz="0 0.325 0" rpy="0 0 0"/>
    <axis xyz="0 1 0"/>
    <dynamics damping="0.2"/>
  </joint>

  <joint name="right_wheel_joint" type="continuous">
    <parent link="base_link"/>
    <child link="right_wheel"/>
    <origin xyz="0 -0.325 0" rpy="0 0 0"/>
    <axis xyz="0 1 0"/>
    <dynamics damping="0.2"/>
  </joint>

  <!-- Lidar -->
  <link name="lidar_link">
    <inertial>
      <origin xyz="0 0 0" rpy="0 0 0"/>
      <mass value="0.5"/>
      <inertia ixx="0.01" ixy="0.0" ixz="0.0" iyy="0.01" iyz="0.0" izz="0.01"/>
    </inertial>
    <visual>
      <origin xyz="0 0 0" rpy="0 0 0"/>
      <geometry>
        <cylinder radius="0.05" length="0.06"/>
      </geometry>
      <material name="black"/>
    </visual>
    <collision>
      <origin xyz="0 0 0" rpy="0 0 0"/>
      <geometry>
        <cylinder radius="0.05" length="0.06"/>
      </geometry>
    </collision>
  </link>

  <joint name="lidar_joint" type="fixed">
    <parent link="base_link"/>
    <child link="lidar_link"/>
    <origin xyz="0.3 0 0.15" rpy="0 0 0"/>
  </joint>

  <!-- Camera -->
  <link name="camera_link">
    <inertial>
      <origin xyz="0 0 0" rpy="0 0 0"/>
      <mass value="0.2"/>
      <inertia ixx="0.001" ixy="0.0" ixz="0.0" iyy="0.001" iyz="0.0" izz="0.001"/>
    </inertial>
    <visual>
      <origin xyz="0 0 0" rpy="0 0 0"/>
      <geometry>
        <box size="0.04 0.08 0.04"/>
      </geometry>
      <material name="black"/>
    </visual>
    <collision>
      <origin xyz="0 0 0" rpy="0 0 0"/>
      <geometry>
        <box size="0.04 0.08 0.04"/>
      </geometry>
    </collision>
  </link>

  <joint name="camera_joint" type="fixed">
    <parent link="base_link"/>
    <child link="camera_link"/>
    <origin xyz="0.35 0 0.25" rpy="0 0 0"/>
  </joint>

  <!-- Manipulator base -->
  <link name="arm_base_link">
    <inertial>
      <origin xyz="0 0 0.05" rpy="0 0 0"/>
      <mass value="5.0"/>
      <inertia ixx="0.1" ixy="0.0" ixz="0.0" iyy="0.1" iyz="0.0" izz="0.1"/>
    </inertial>
    <visual>
      <origin xyz="0 0 0.05" rpy="0 0 0"/>
      <geometry>
        <cylinder radius="0.06" length="0.1"/>
      </geometry>
      <material name="dark_grey"/>
    </visual>
    <collision>
      <origin xyz="0 0 0.05" rpy="0 0 0"/>
      <geometry>
        <cylinder radius="0.06" length="0.1"/>
      </geometry>
    </collision>
  </link>

  <joint name="arm_base_joint" type="fixed">
    <parent link="base_link"/>
    <child link="arm_base_link"/>
    <origin xyz="0 0 0.1" rpy="0 0 0"/>
  </joint>

  <!-- Arm link 1 -->
  <link name="arm_link_1">
    <inertial>
      <origin xyz="0 0 0.1" rpy="0 0 0"/>
      <mass value="3.0"/>
      <inertia ixx="0.05" ixy="0.0" ixz="0.0" iyy="0.05" iyz="0.0" izz="0.01"/>
    </inertial>
    <visual>
      <origin xyz="0 0 0.1" rpy="0 0 0"/>
      <geometry>
        <cylinder radius="0.04" length="0.2"/>
      </geometry>
      <material name="light_grey"/>
    </visual>
    <collision>
      <origin xyz="0 0 0.1" rpy="0 0 0"/>
      <geometry>
        <cylinder radius="0.04" length="0.2"/>
      </geometry>
    </collision>
  </link>

  <joint name="arm_joint_1" type="revolute">
    <parent link="arm_base_link"/>
    <child link="arm_link_1"/>
    <origin xyz="0 0 0.1" rpy="0 0 0"/>
    <axis xyz="0 0 1"/>
    <limit lower="-3.14" upper="3.14" effort="100" velocity="1.0"/>
    <dynamics damping="0.1"/>
  </joint>

  <!-- Arm link 2 -->
  <link name="arm_link_2">
    <inertial>
      <origin xyz="0.15 0 0" rpy="0 0 0"/>
      <mass value="2.5"/>
      <inertia ixx="0.01" ixy="0.0" ixz="0.0" iyy="0.08" iyz="0.0" izz="0.08"/>
    </inertial>
    <visual>
      <origin xyz="0.15 0 0" rpy="0 1.5707 0"/>
      <geometry>
        <cylinder radius="0.035" length="0.3"/>
      </geometry>
      <material name="light_grey"/>
    </visual>
    <collision>
      <origin xyz="0.15 0 0" rpy="0 1.5707 0"/>
      <geometry>
        <cylinder radius="0.035" length="0.3"/>
      </geometry>
    </collision>
  </link>

  <joint name="arm_joint_2" type="revolute">
    <parent link="arm_link_1"/>
    <child link="arm_link_2"/>
    <origin xyz="0 0 0.2" rpy="0 0 0"/>
    <axis xyz="0 1 0"/>
    <limit lower="-1.57" upper="1.57" effort="100" velocity="1.0"/>
    <dynamics damping="0.1"/>
  </joint>

  <!-- Arm link 3 -->
  <link name="arm_link_3">
    <inertial>
      <origin xyz="0.12 0 0" rpy="0 0 0"/>
      <mass value="2.0"/>
      <inertia ixx="0.01" ixy="0.0" ixz="0.0" iyy="0.05" iyz="0.0" izz="0.05"/>
    </inertial>
    <visual>
      <origin xyz="0.12 0 0" rpy="0 1.5707 0"/>
      <geometry>
        <cylinder radius="0.03" length="0.24"/>
      </geometry>
      <material name="light_grey"/>
    </visual>
    <collision>
      <origin xyz="0.12 0 0" rpy="0 1.5707 0"/>
      <geometry>
        <cylinder radius="0.03" length="0.24"/>
      </geometry>
    </collision>
  </link>

  <joint name="arm_joint_3" type="revolute">
    <parent link="arm_link_2"/>
    <child link="arm_link_3"/>
    <origin xyz="0.3 0 0" rpy="0 0 0"/>
    <axis xyz="0 1 0"/>
    <limit lower="-2.0" upper="2.0" effort="100" velocity="1.0"/>
    <dynamics damping="0.1"/>
  </joint>

  <!-- Arm link 4 (wrist roll) -->
  <link name="arm_link_4">
    <inertial>
      <origin xyz="0.08 0 0" rpy="0 0 0"/>
      <mass value="1.5"/>
      <inertia ixx="0.005" ixy="0.0" ixz="0.0" iyy="0.02" iyz="0.0" izz="0.02"/>
    </inertial>
    <visual>
      <origin xyz="0.08 0 0" rpy="0 1.5707 0"/>
      <geometry>
        <cylinder radius="0.025" length="0.16"/>
      </geometry>
      <material name="light_grey"/>
    </visual>
    <collision>
      <origin xyz="0.08 0 0" rpy="0 1.5707 0"/>
      <geometry>
        <cylinder radius="0.025" length="0.16"/>
      </geometry>
    </collision>
  </link>

  <joint name="arm_joint_4" type="revolute">
    <parent link="arm_link_3"/>
    <child link="arm_link_4"/>
    <origin xyz="0.24 0 0" rpy="0 0 0"/>
    <axis xyz="1 0 0"/>
    <limit lower="-3.14" upper="3.14" effort="50" velocity="1.0"/>
    <dynamics damping="0.1"/>
  </joint>

  <!-- Arm link 5 (wrist pitch) -->
  <link name="arm_link_5">
    <inertial>
      <origin xyz="0 0 0" rpy="0 0 0"/>
      <mass value="1.0"/>
      <inertia ixx="0.005" ixy="0.0" ixz="0.0" iyy="0.005" iyz="0.0" izz="0.005"/>
    </inertial>
    <visual>
      <origin xyz="0 0 0" rpy="0 0 0"/>
      <geometry>
        <cylinder radius="0.02" length="0.06"/>
      </geometry>
      <material name="dark_grey"/>
    </visual>
    <collision>
      <origin xyz="0 0 0" rpy="0 0 0"/>
      <geometry>
        <cylinder radius="0.02" length="0.06"/>
      </geometry>
    </collision>
  </link>

  <joint name="arm_joint_5" type="revolute">
    <parent link="arm_link_4"/>
    <child link="arm_link_5"/>
    <origin xyz="0.16 0 0" rpy="0 0 0"/>
    <axis xyz="0 1 0"/>
    <limit lower="-1.57" upper="1.57" effort="50" velocity="1.0"/>
    <dynamics damping="0.1"/>
  </joint>

  <!-- Arm link 6 (wrist yaw) -->
  <link name="arm_link_6">
    <inertial>
      <origin xyz="0 0 0.04" rpy="0 0 0"/>
      <mass value="0.8"/>
      <inertia ixx="0.003" ixy="0.0" ixz="0.0" iyy="0.003" iyz="0.0" izz="0.003"/>
    </inertial>
    <visual>
      <origin xyz="0 0 0.04" rpy="0 0 0"/>
      <geometry>
        <cylinder radius="0.015" length="0.08"/>
      </geometry>
      <material name="dark_grey"/>
    </visual>
    <collision>
      <origin xyz="0 0 0.04" rpy="0 0 0"/>
      <geometry>
        <cylinder radius="0.015" length="0.08"/>
      </geometry>
    </collision>
  </link>

  <joint name="arm_joint_6" type="revolute">
    <parent link="arm_link_5"/>
    <child link="arm_link_6"/>
    <origin xyz="0 0 0.03" rpy="0 0 0"/>
    <axis xyz="0 0 1"/>
    <limit lower="-3.14" upper="3.14" effort="30" velocity="1.0"/>
    <dynamics damping="0.1"/>
  </joint>

  <!-- Gripper base -->
  <link name="gripper_base_link">
    <inertial>
      <origin xyz="0 0 0.02" rpy="0 0 0"/>
      <mass value="0.5"/>
      <inertia ixx="0.001" ixy="0.0" ixz="0.0" iyy="0.001" iyz="0.0" izz="0.001"/>
    </inertial>
    <visual>
      <origin xyz="0 0 0.02" rpy="0 0 0"/>
      <geometry>
        <box size="0.06 0.04 0.04"/>
      </geometry>
      <material name="black"/>
    </visual>
    <collision>
      <origin xyz="0 0 0.02" rpy="0 0 0"/>
      <geometry>
        <box size="0.06 0.04 0.04"/>
      </geometry>
    </collision>
  </link>

  <joint name="gripper_base_joint" type="fixed">
    <parent link="arm_link_6"/>
    <child link="gripper_base_link"/>
    <origin xyz="0 0 0.08" rpy="0 0 0"/>
  </joint>

  <!-- Left gripper finger -->
  <link name="gripper_left_finger">
    <inertial>
      <origin xyz="0 0 0.03" rpy="0 0 0"/>
      <mass value="0.1"/>
      <inertia ixx="0.0001" ixy="0.0" ixz="0.0" iyy="0.0001" iyz="0.0" izz="0.0001"/>
    </inertial>
    <visual>
      <origin xyz="0 0 0.03" rpy="0 0 0"/>
      <geometry>
        <box size="0.01 0.02 0.06"/>
      </geometry>
      <material name="white"/>
    </visual>
    <collision>
      <origin xyz="0 0 0.03" rpy="0 0 0"/>
      <geometry>
        <box size="0.01 0.02 0.06"/>
      </geometry>
    </collision>
  </link>

  <joint name="gripper_left_joint" type="prismatic">
    <parent link="gripper_base_link"/>
    <child link="gripper_left_finger"/>
    <origin xyz="0.02 0.015 0.04" rpy="0 0 0"/>
    <axis xyz="0 1 0"/>
    <limit lower="0" upper="0.04" effort="10" velocity="0.1"/>
    <dynamics damping="0.1"/>
  </joint>

  <!-- Right gripper finger -->
  <link name="gripper_right_finger">
    <inertial>
      <origin xyz="0 0 0.03" rpy="0 0 0"/>
      <mass value="0.1"/>
      <inertia ixx="0.0001" ixy="0.0" ixz="0.0" iyy="0.0001" iyz="0.0" izz="0.0001"/>
    </inertial>
    <visual>
      <origin xyz="0 0 0.03" rpy="0 0 0"/>
      <geometry>
        <box size="0.01 0.02 0.06"/>
      </geometry>
      <material name="white"/>
    </visual>
    <collision>
      <origin xyz="0 0 0.03" rpy="0 0 0"/>
      <geometry>
        <box size="0.01 0.02 0.06"/>
      </geometry>
    </collision>
  </link>

  <joint name="gripper_right_joint" type="prismatic">
    <parent link="gripper_base_link"/>
    <child link="gripper_right_finger"/>
    <origin xyz="0.02 -0.015 0.04" rpy="0 0 0"/>
    <axis xyz="0 -1 0"/>
    <limit lower="0" upper="0.04" effort="10" velocity="0.1"/>
    <dynamics damping="0.1"/>
  </joint>

  <!-- End effector frame -->
  <link name="end_effector_link"/>
  
  <joint name="end_effector_joint" type="fixed">
    <parent link="gripper_base_link"/>
    <child link="end_effector_link"/>
    <origin xyz="0.03 0 0.1" rpy="0 0 0"/>
  </joint>

</robot>